<sdf version='1.6'>
  <model name='turtlebot3_wheelchair'>
    <link name='base_footprint'>
      <pose frame=''>0 0 0 0 -0 0</pose>
      <inertial>
        <pose frame=''>-0.027138 0.159683 0.371397 0 -0 0</pose>
        <mass>14.4001</mass>
        <inertia>
          <ixx>2.2985</ixx>
          <ixy>0.087743</ixy>
          <ixz>-0.0360628</ixz>
          <iyy>1.41914</iyy>
          <iyz>0.869052</iyz>
          <izz>1.63708</izz>
        </inertia>
      </inertial>
      <collision name='base_footprint_fixed_joint_lump__base_link_collision'>
        <pose frame=''>0 0 0.2 0 -0 0</pose>
        <geometry>
          <mesh>
            <scale>1 1 1</scale>
            <uri>model://turtlebot3_description/meshes/wheelchair/base_link.STL</uri>
          </mesh>
        </geometry>
      </collision>
      <collision name='base_footprint_fixed_joint_lump__imu_link_collision_1'>
        <pose frame=''>-0.11663 -0.29369 0.75255 -1.5708 -0 -1.5708</pose>
        <geometry>
          <mesh>
            <scale>1 1 1</scale>
            <uri>model://turtlebot3_description/meshes/wheelchair/imu_link.STL</uri>
          </mesh>
        </geometry>
      </collision>
      <collision name='base_footprint_fixed_joint_lump__support_left_feet_link_collision_2'>
        <pose frame=''>-0.23495 0.62055 0.09372 0.34907 -0 0</pose>
        <geometry>
          <mesh>
            <scale>1 1 1</scale>
            <uri>model://turtlebot3_description/meshes/wheelchair/support_left_feet_link.STL</uri>
          </mesh>
        </geometry>
      </collision>
      <collision name='base_footprint_fixed_joint_lump__support_right_feet_link_collision_3'>
        <pose frame=''>0.20315 0.62055 0.09372 0.34907 -0 0</pose>
        <geometry>
          <mesh>
            <scale>1 1 1</scale>
            <uri>model://turtlebot3_description/meshes/wheelchair/support_right_feet_link.STL</uri>
          </mesh>
        </geometry>
      </collision>
      <collision name='base_footprint_fixed_joint_lump__tube_link_collision_4'>
        <pose frame=''>-0.1859 -0.1665 0.81171 1.7382 -0 0</pose>
        <geometry>
          <mesh>
            <scale>1 1 1</scale>
            <uri>model://turtlebot3_description/meshes/wheelchair/tube_link.STL</uri>
          </mesh>
        </geometry>
      </collision>
      <collision name='base_footprint_fixed_joint_lump__suport_kinect_link_collision_5'>
        <pose frame=''>-0.0632 -0.259809 1.36388 -0.2618 0 0</pose>
        <geometry>
          <mesh>
            <scale>1 1 1</scale>
            <uri>model://turtlebot3_description/meshes/wheelchair/suport_kinect_link.STL</uri>
          </mesh>
        </geometry>
      </collision>
      <collision name='base_footprint_fixed_joint_lump__base_scan_link_collision_6'>
        <pose frame=''>-0.015197 -0.233251 1.40664 1.8326 2e-06 3.14159</pose>
        <geometry>
          <mesh>
            <scale>1 1 1</scale>
            <uri>model://turtlebot3_description/meshes/wheelchair/base_scan_link.STL</uri>
          </mesh>
        </geometry>
      </collision>
      <visual name='base_footprint_fixed_joint_lump__base_link_visual'>
        <pose frame=''>0 0 0.2 0 -0 0</pose>
        <geometry>
          <mesh>
            <scale>1 1 1</scale>
            <uri>model://turtlebot3_description/meshes/wheelchair/base_link.STL</uri>
          </mesh>
        </geometry>
      </visual>
      <visual name='base_footprint_fixed_joint_lump__imu_link_visual_1'>
        <pose frame=''>-0.11663 -0.29369 0.75255 -1.5708 -0 -1.5708</pose>
        <geometry>
          <mesh>
            <scale>1 1 1</scale>
            <uri>model://turtlebot3_description/meshes/wheelchair/imu_link.STL</uri>
          </mesh>
        </geometry>
      </visual>
      <visual name='base_footprint_fixed_joint_lump__support_left_feet_link_visual_2'>
        <pose frame=''>-0.23495 0.62055 0.09372 0.34907 -0 0</pose>
        <geometry>
          <mesh>
            <scale>1 1 1</scale>
            <uri>model://turtlebot3_description/meshes/wheelchair/support_left_feet_link.STL</uri>
          </mesh>
        </geometry>
      </visual>
      <visual name='base_footprint_fixed_joint_lump__support_right_feet_link_visual_3'>
        <pose frame=''>0.20315 0.62055 0.09372 0.34907 -0 0</pose>
        <geometry>
          <mesh>
            <scale>1 1 1</scale>
            <uri>model://turtlebot3_description/meshes/wheelchair/support_right_feet_link.STL</uri>
          </mesh>
        </geometry>
      </visual>
      <visual name='base_footprint_fixed_joint_lump__tube_link_visual_4'>
        <pose frame=''>-0.1859 -0.1665 0.81171 1.7382 -0 0</pose>
        <geometry>
          <mesh>
            <scale>1 1 1</scale>
            <uri>model://turtlebot3_description/meshes/wheelchair/tube_link.STL</uri>
          </mesh>
        </geometry>
      </visual>
      <visual name='base_footprint_fixed_joint_lump__suport_kinect_link_visual_5'>
        <pose frame=''>-0.0632 -0.259809 1.36388 -0.2618 0 0</pose>
        <geometry>
          <mesh>
            <scale>1 1 1</scale>
            <uri>model://turtlebot3_description/meshes/wheelchair/suport_kinect_link.STL</uri>
          </mesh>
        </geometry>
      </visual>
      <visual name='base_footprint_fixed_joint_lump__base_scan_link_visual_6'>
        <pose frame=''>-0.015197 -0.233251 1.40664 1.8326 2e-06 3.14159</pose>
        <geometry>
          <mesh>
            <scale>1 1 1</scale>
            <uri>model://turtlebot3_description/meshes/wheelchair/base_scan_link.STL</uri>
          </mesh>
        </geometry>
      </visual>
    </link>
    <link name='support_small_left_wheel_link'>
      <pose frame=''>-0.23971 0.2776 0.1619 0 -0 0</pose>
      <inertial>
        <pose frame=''>0.023813 0.00695 -0.016441 0 -0 0</pose>
        <mass>0.1</mass>
        <inertia>
          <ixx>0.0001406</ixx>
          <ixy>1.3515e-11</ixy>
          <ixz>5.252e-12</ixz>
          <iyy>0.00015091</iyy>
          <iyz>-3.0634e-05</iyz>
          <izz>4.0905e-05</izz>
        </inertia>
      </inertial>
      <collision name='support_small_left_wheel_link_collision'>
        <pose frame=''>0 0 0 0 -0 0</pose>
        <geometry>
          <mesh>
            <scale>1 1 1</scale>
            <uri>model://turtlebot3_description/meshes/wheelchair/support_small_left_wheel_link.STL</uri>
          </mesh>
        </geometry>
      </collision>
      <visual name='support_small_left_wheel_link_visual'>
        <pose frame=''>0 0 0 0 -0 0</pose>
        <geometry>
          <mesh>
            <scale>1 1 1</scale>
            <uri>model://turtlebot3_description/meshes/wheelchair/support_small_left_wheel_link.STL</uri>
          </mesh>
        </geometry>
      </visual>
    </link>
    <joint name='support_small_left_wheel_joint' type='revolute'>
      <child>support_small_left_wheel_link</child>
      <parent>base_footprint</parent>
      <axis>
        <xyz>0 0 1</xyz>
        <limit>
          <lower>0</lower>
          <upper>0</upper>
          <effort>0</effort>
          <velocity>0</velocity>
        </limit>
        <dynamics>
          <spring_reference>0</spring_reference>
          <spring_stiffness>0</spring_stiffness>
        </dynamics>
        <use_parent_model_frame>1</use_parent_model_frame>
      </axis>
    </joint>
    <link name='small_left_wheel_link'>
      <pose frame=''>-0.215897 0.240135 0.05395 0 -0 0</pose>
      <inertial>
        <pose frame=''>-0 0 -0 0 -0 0</pose>
        <mass>1</mass>
        <inertia>
          <ixx>0.00077012</ixx>
          <ixy>-7.3968e-20</ixy>
          <ixz>-2.6043e-21</ixz>
          <iyy>0.00040333</iyy>
          <iyz>-9.7969e-21</iyz>
          <izz>0.00040333</izz>
        </inertia>
      </inertial>
      <collision name='small_left_wheel_link_collision'>
        <pose frame=''>0 0 0 0 -0 0</pose>
        <geometry>
          <mesh>
            <scale>1 1 1</scale>
            <uri>model://turtlebot3_description/meshes/wheelchair/small_left_wheel_link.STL</uri>
          </mesh>
        </geometry>
      </collision>
      <visual name='small_left_wheel_link_visual'>
        <pose frame=''>0 0 0 0 -0 0</pose>
        <geometry>
          <mesh>
            <scale>1 1 1</scale>
            <uri>model://turtlebot3_description/meshes/wheelchair/small_left_wheel_link.STL</uri>
          </mesh>
        </geometry>
      </visual>
    </link>
    <joint name='small_left_wheel_joint' type='revolute'>
      <child>small_left_wheel_link</child>
      <parent>support_small_left_wheel_link</parent>
      <axis>
        <xyz>-1 0 0</xyz>
        <limit>
          <lower>-1e+16</lower>
          <upper>1e+16</upper>
        </limit>
        <dynamics>
          <spring_reference>0</spring_reference>
          <spring_stiffness>0</spring_stiffness>
        </dynamics>
        <use_parent_model_frame>1</use_parent_model_frame>
      </axis>
    </joint>
    <link name='support_small_right_wheel_link'>
      <pose frame=''>0.20791 0.2776 0.1619 0 -0 0</pose>
      <inertial>
        <pose frame=''>-0.023812 0.00695 -0.016441 0 -0 0</pose>
        <mass>1</mass>
        <inertia>
          <ixx>0.0001406</ixx>
          <ixy>1.3515e-11</ixy>
          <ixz>5.252e-12</ixz>
          <iyy>0.00015091</iyy>
          <iyz>-3.0634e-05</iyz>
          <izz>4.0905e-05</izz>
        </inertia>
      </inertial>
      <collision name='support_small_right_wheel_link_collision'>
        <pose frame=''>0 0 0 0 -0 0</pose>
        <geometry>
          <mesh>
            <scale>1 1 1</scale>
            <uri>model://turtlebot3_description/meshes/wheelchair/support_small_right_wheel_link.STL</uri>
          </mesh>
        </geometry>
      </collision>
      <visual name='support_small_right_wheel_link_visual'>
        <pose frame=''>0 0 0 0 -0 0</pose>
        <geometry>
          <mesh>
            <scale>1 1 1</scale>
            <uri>model://turtlebot3_description/meshes/wheelchair/support_small_right_wheel_link.STL</uri>
          </mesh>
        </geometry>
      </visual>
    </link>
    <joint name='support_small_right_wheel_joint' type='revolute'>
      <child>support_small_right_wheel_link</child>
      <parent>base_footprint</parent>
      <axis>
        <xyz>0 0 1</xyz>
        <limit>
          <lower>0</lower>
          <upper>0</upper>
          <effort>0</effort>
          <velocity>0</velocity>
        </limit>
        <dynamics>
          <spring_reference>0</spring_reference>
          <spring_stiffness>0</spring_stiffness>
        </dynamics>
        <use_parent_model_frame>1</use_parent_model_frame>
      </axis>
    </joint>
    <link name='small_right_wheel_link'>
      <pose frame=''>0.184097 0.240135 0.05395 0 -0 0</pose>
      <inertial>
        <pose frame=''>-0 0 0 0 -0 0</pose>
        <mass>1</mass>
        <inertia>
          <ixx>0.00077012</ixx>
          <ixy>-9.9115e-20</ixy>
          <ixz>-2.0641e-20</ixz>
          <iyy>0.00040333</iyy>
          <iyz>-3.6137e-20</iyz>
          <izz>0.00040333</izz>
        </inertia>
      </inertial>
      <collision name='small_right_wheel_link_collision'>
        <pose frame=''>0 0 0 0 -0 0</pose>
        <geometry>
          <mesh>
            <scale>1 1 1</scale>
            <uri>model://turtlebot3_description/meshes/wheelchair/small_right_wheel_link.STL</uri>
          </mesh>
        </geometry>
      </collision>
      <visual name='small_right_wheel_link_visual'>
        <pose frame=''>0 0 0 0 -0 0</pose>
        <geometry>
          <mesh>
            <scale>1 1 1</scale>
            <uri>model://turtlebot3_description/meshes/wheelchair/small_right_wheel_link.STL</uri>
          </mesh>
        </geometry>
      </visual>
    </link>
    <joint name='small_right_wheel_joint' type='revolute'>
      <child>small_right_wheel_link</child>
      <parent>support_small_right_wheel_link</parent>
      <axis>
        <xyz>-1 0 0</xyz>
        <limit>
          <lower>-1e+16</lower>
          <upper>1e+16</upper>
        </limit>
        <dynamics>
          <spring_reference>0</spring_reference>
          <spring_stiffness>0</spring_stiffness>
        </dynamics>
        <use_parent_model_frame>1</use_parent_model_frame>
      </axis>
    </joint>
    <link name='wheel_left_link'>
      <pose frame=''>-0.2413 -0.14129 0.2635 0 -0 0</pose>
      <inertial>
        <pose frame=''>-0.0381 -0 -0 0 -0 0</pose>
        <mass>1</mass>
        <inertia>
          <ixx>0.056951</ixx>
          <ixy>5.4213e-18</ixy>
          <ixz>-1.6817e-18</ixz>
          <iyy>0.028611</iyy>
          <iyz>-2.9984e-17</iyz>
          <izz>0.028611</izz>
        </inertia>
      </inertial>
      <collision name='wheel_left_link_collision'>
        <pose frame=''>0 0 0 0 -0 0</pose>
        <geometry>
          <mesh>
            <scale>1 1 1</scale>
            <uri>model://turtlebot3_description/meshes/wheelchair/wheel_left_link.STL</uri>
          </mesh>
        </geometry>
      </collision>
      <visual name='wheel_left_link_visual'>
        <pose frame=''>0 0 0 0 -0 0</pose>
        <geometry>
          <mesh>
            <scale>1 1 1</scale>
            <uri>model://turtlebot3_description/meshes/wheelchair/wheel_left_link.STL</uri>
          </mesh>
        </geometry>
      </visual>
    </link>
    <joint name='wheel_left_joint' type='revolute'>
      <child>wheel_left_link</child>
      <parent>base_footprint</parent>
      <axis>
        <xyz>-1 0 0</xyz>
        <limit>
          <lower>-1e+16</lower>
          <upper>1e+16</upper>
        </limit>
        <dynamics>
          <spring_reference>0</spring_reference>
          <spring_stiffness>0</spring_stiffness>
        </dynamics>
        <use_parent_model_frame>1</use_parent_model_frame>
      </axis>
    </joint>
    <link name='wheel_right_link'>
      <pose frame=''>0.2095 -0.14129 0.2635 0 -0 0</pose>
      <inertial>
        <pose frame=''>0.0381 0 0 0 -0 0</pose>
        <mass>1</mass>
        <inertia>
          <ixx>0.056951</ixx>
          <ixy>-5.6452e-21</ixy>
          <ixz>1.2476e-18</ixz>
          <iyy>0.028611</iyy>
          <iyz>3.59e-19</iyz>
          <izz>0.028611</izz>
        </inertia>
      </inertial>
      <collision name='wheel_right_link_collision'>
        <pose frame=''>0 0 0 0 -0 0</pose>
        <geometry>
          <mesh>
            <scale>1 1 1</scale>
            <uri>model://turtlebot3_description/meshes/wheelchair/wheel_right_link.STL</uri>
          </mesh>
        </geometry>
      </collision>
      <visual name='wheel_right_link_visual'>
        <pose frame=''>0 0 0 0 -0 0</pose>
        <geometry>
          <mesh>
            <scale>1 1 1</scale>
            <uri>model://turtlebot3_description/meshes/wheelchair/wheel_right_link.STL</uri>
          </mesh>
        </geometry>
      </visual>
    </link>
    <joint name='wheel_right_joint' type='revolute'>
      <child>wheel_right_link</child>
      <parent>base_footprint</parent>
      <axis>
        <xyz>-1 0 0</xyz>
        <limit>
          <lower>-1e+16</lower>
          <upper>1e+16</upper>
        </limit>
        <dynamics>
          <spring_reference>0</spring_reference>
          <spring_stiffness>0</spring_stiffness>
        </dynamics>
        <use_parent_model_frame>1</use_parent_model_frame>
      </axis>
    </joint>
  </model>
</sdf>
